"traceback": "  File \"/home/vagrant/devel/pulpcore/pulpcore/tasking/pulpcore_worker.py\", line 452, in _perform_task
    result = func(*args, **kwargs)
  File \"/home/vagrant/devel/pulp_file/pulp_file/app/tasks/synchronizing.py\", line 51, in synchronize
    rv = dv.create()
  File \"/home/vagrant/devel/pulpcore/pulpcore/plugin/stages/declarative_version.py\", line 161, in create
    loop.run_until_complete(pipeline)
  File \"/usr/lib64/python3.10/asyncio/base_events.py\", line 646, in run_until_complete
    return future.result()
  File \"/home/vagrant/devel/pulpcore/pulpcore/plugin/stages/api.py\", line 225, in create_pipeline
    await asyncio.gather(*futures)
  File \"/home/vagrant/devel/pulpcore/pulpcore/plugin/stages/api.py\", line 43, in __call__
    await self.run()
  File \"/home/vagrant/devel/pulpcore/pulpcore/plugin/stages/content_stages.py\", line 198, in run
    await sync_to_async(process_batch)()
  File \"/usr/local/lib/pulp/lib64/python3.10/site-packages/asgiref/sync.py\", line 435, in __call__
    ret = await asyncio.wait_for(future, timeout=None)
  File \"/usr/lib64/python3.10/asyncio/tasks.py\", line 408, in wait_for
    return await fut
  File \"/usr/lib64/python3.10/concurrent/futures/thread.py\", line 58, in run
    result = self.fn(*self.args, **self.kwargs)
  File \"/usr/local/lib/pulp/lib64/python3.10/site-packages/asgiref/sync.py\", line 476, in thread_handler
    return func(*args, **kwargs)
  File \"/home/vagrant/devel/pulpcore/pulpcore/plugin/stages/content_stages.py\", line 187, in process_batch
    ContentArtifact.objects.bulk_update(to_update_ca_bulk, [\"artifact\"])
  File \"/usr/local/lib/pulp/lib64/python3.10/site-packages/django/db/models/manager.py\", line 85, in manager_method
    return getattr(self.get_queryset(), name)(*args, **kwargs)
  File \"/usr/local/lib/pulp/lib64/python3.10/site-packages/django/db/models/query.py\", line 568, in bulk_update
    self.filter(pk__in=pks).update(**update_kwargs)
  File \"/usr/local/lib/pulp/lib64/python3.10/site-packages/django/db/models/query.py\", line 783, in update
    rows = query.get_compiler(self.db).execute_sql(CURSOR)
  File \"/usr/local/lib/pulp/lib64/python3.10/site-packages/django/db/models/sql/compiler.py\", line 1559, in execute_sql
    cursor = super().execute_sql(result_type)
  File \"/usr/local/lib/pulp/lib64/python3.10/site-packages/django/db/models/sql/compiler.py\", line 1175, in execute_sql
    cursor.execute(sql, params)
  File \"/usr/local/lib/pulp/lib64/python3.10/site-packages/django/db/backends/utils.py\", line 66, in execute
    return self._execute_with_wrappers(sql, params, many=False, executor=self._execute)
  File \"/usr/local/lib/pulp/lib64/python3.10/site-packages/django/db/backends/utils.py\", line 75, in _execute_with_wrappers
    return executor(sql, params, many, context)
  File \"/usr/local/lib/pulp/lib64/python3.10/site-packages/django/db/backends/utils.py\", line 79, in _execute
    with self.db.wrap_database_errors:
  File \"/usr/local/lib/pulp/lib64/python3.10/site-packages/django/db/utils.py\", line 90, in __exit__
    raise dj_exc_value.with_traceback(traceback) from exc_value
  File \"/usr/local/lib/pulp/lib64/python3.10/site-packages/django/db/backends/utils.py\", line 84, in _execute
    return self.cursor.execute(sql, params)
",
      "description": "deadlock detected
DETAIL:  Process 182825 waits for ShareLock on transaction 7865238; blocked by process 182774.
Process 182774 waits for ShareLock on transaction 7865236; blocked by process 182825.
HINT:  See server log for query details.
CONTEXT:  while rechecking updated tuple (63,20) in relation \"core_contentartifact\"
"

